<?xml version="1.0"?>
<robot xmlns:xacro="http://www.ros.org/wiki/xacro" >
    <material name="white">
        <color rgba="1 1 1 1" />
    </material>
    <material name="orange">
        <color rgba="1 0.3 0.1 1" />
    </material>
    <material name="blue">
        <color rgba="0 0 1 1" />
    </material>
    <material name="black">
        <color rgba="0 0 0 1" />
    </material>

    <!--Define inertial property macro -->
    <xacro:macro name="box_inertial" params="m w d h">
        <inertial>
            <origin xyz="0.15 0.0 0.75" rpy="0.0 0.0 0.0"/>
            <mass value="${m}"/>
            <inertia ixx="${(m/12) * (h*h + d*d)}" ixy="0.0" ixz="0.0" iyy="${(m/12) * (w*w + h*h)}" iyz="0.0" izz="${(m/12) * (w*w + d*d)}"/>
        </inertial>
    </xacro:macro>

    <xacro:macro name="cylinder_inertia" params="m r h">
        <inertial>
            <origin xyz="0.0 0.0 0.0" rpy="0.0 0.0 0.0"/>
            <mass value="${m}"/>
            <inertia ixx="${(m/12) * (3*r*r + h*h)}" ixy="0.0" ixz="0.0" iyy="${(m/12) * (3*r*r + h*h)}" iyz="0.0" izz="${(m/2) * (r * r)}"/>
        </inertial>
    </xacro:macro>

    <xacro:macro name="sphere_inertia" params="m r">
        <inertial>
            <origin xyz="0.0 0.0 0.0" rpy="0.0 0.0 0.0"/>
            <mass value="${m}"/>
            <inertia ixx="${(2/5) * m * (r*r)}" ixy="0.0" ixz="0.0" iyy="${(2/5) * m * (r*r)}" iyz="0.0" izz="${(2/5) * m * (r*r)}"/>
        </inertial>
    </xacro:macro>

    <!--base link-->
    <link name="base_link">
    
    </link>

    <!--chassis link-->
    <link name="chassis">
        <visual>
            <geometry>
                <box size="0.3 0.3 0.15"/>
            </geometry>
            <material name="white" />
            <origin xyz="0.15 0.0 0.075" rpy="0.0 0.0 0.0"/>
            
        </visual>
        <collision>
            <geometry>
                <box size="0.3 0.3 0.15"/>
            </geometry>
            <origin xyz="0.15 0.0 0.075" rpy="0.0 0.0 0.0"/>            
        </collision>
        <xacro:box_inertial m="0.5" w="0.3" d="0.3" h="0.15"/>
    </link>

    <gazebo reference="chassis">
        <material>Gazebo/Orange</material>
    </gazebo>

    <joint name="chassis_joint" type="fixed">
        <parent link="base_link"/>
        <child link="chassis"/>
        <origin xyz="-0.1 0.0 0.0" rpy="0.0 0.0 0.0"/>
    </joint>
    
    <!--left wheel link-->
    <link name="left_wheel">
        <visual>
            <geometry>
                <cylinder radius="0.05" length="0.04"/>
            </geometry>
            <material name="blue" />
        </visual>
        <collision>
            <geometry>
                <cylinder radius="0.05" length="0.04"/>
            </geometry>
        </collision>
        <xacro:cylinder_inertia m="0.1" r="0.05" h="0.04" />
    </link>

    <gazebo reference="left_wheel">
        <material>Gazebo/Blue</material>
    </gazebo>

    <joint name="left_wheel_joint" type="continuous">
        <parent link="base_link"/>
        <child link="left_wheel"/>
        <axis xyz="0 0 1"/>
        <origin xyz="0 0.175 0" rpy="-${pi/2} 0 0"/>
    </joint>
    

    <!--right wheel link-->
    <link name="right_wheel">
        <visual>
            <geometry>
                <cylinder radius="0.05" length="0.04"/>
            </geometry>
            <material name="blue" />
              
            <!--  -->
        </visual>
        <collision>
            <geometry>
                <cylinder radius="0.05" length="0.04"/>
            </geometry>
        </collision>
        <xacro:cylinder_inertia m="0.1" r="0.05" h="0.04" />
    </link>


    <gazebo reference="right_wheel">
        <material>Gazebo/Blue</material>
    </gazebo>

    <joint name="right_wheel_joint" type="continuous">
        <parent link="base_link"/>
        <child link="right_wheel"/>
        <axis xyz="0 0 -1"/>
        <origin xyz="0 -0.175 0" rpy="${pi/2} 0 0"/>
    </joint>

    <!-- caster wheel link-->
     <link name="caster_wheel">
        <visual>
            <geometry>
                <sphere radius="0.05"/>
            </geometry>
            <material name="black" />
        </visual>
        <collision>
            <geometry>
                <sphere radius="0.05"/>
            </geometry>
        </collision>
        <xacro:sphere_inertia m="0.5" r="0.05" />
     </link>

     <gazebo reference="caster_wheel">
        <material>Gazebo/Black</material>
        <mu1 value="0.001" />
        <mu2 value="0.001" />
    </gazebo>

     <joint name="caster_wheel_joint" type="fixed">
        <parent link="chassis"/>
        <child link="caster_wheel"/>
        <origin xyz="0.24 0.0 0.0" rpy="0.0 0.0 0.0"/>
     </joint>
     
     
</robot>